<mujoco model="SATYRR_OLD_V2">
    <compiler eulerseq = "zyx" angle="radian" coordinate="local" meshdir="satyrr_wholebody/"/>
    <size njmax="-1" nconmax="-1" />
    <option integrator="RK4" timestep="0.001" solver="PGS"/>

	<default>
		<geom contype = '0' conaffinity = '0'/>
		<default class = 'collision-default'>
			<geom contype = '6' conaffinity = '0'/>
		</default>
        <default class = 'collision-group-a'>
            <geom contype = '2' conaffinity = '4'/>
        </default>
        <default class = 'collision-group-b'>
            <geom contype = '4' conaffinity = '2'/>
        </default>
    </default>

    <asset>
        <mesh name="Torso" file="Torso.STL" />
        <mesh name="Thigh_R" file="Thigh_R.STL"/>
        <mesh name="Shin_R" file="Shin_R.STL"/>
        <mesh name="Wheel_R" file="Wheel_R.STL"/>
        <mesh name="Thigh_L" file="Thigh_L.STL"/>
        <mesh name="Shin_L" file="Shin_L.STL"/>
        <mesh name="Wheel_L" file="Wheel_L.STL"/>
        <mesh name="Shoulder_U_L" file="Shoulder_U_L.STL" />
        <mesh name="Shoulder_L" file="Shoulder_L.STL" />
        <mesh name="Arm_L" file="Arm_L.STL"/>
        <mesh name="Shank_L" file="Shank_L.STL"/>
        <mesh name="Shoulder_U_R" file="Shoulder_U_R.STL"/>
        <mesh name="Shoulder_R" file="Shoulder_R.STL"/>
        <mesh name="Arm_R" file="Arm_R.STL"/>
        <mesh name="Shank_R" file="Shank_R.STL"/>
        <mesh name="Hand_L" file="Hand_L.STL"/>
        <mesh name="Hand_R" file="Hand_R.STL"/>
        <texture builtin="checker" height="512" name="texplane" rgb1=".2 .3 .4" rgb2=".1 0.15 0.2" type="2d" width="512"/>
        <material name="floorplane" reflectance="0.5" texrepeat="1 1" texture="texplane" texuniform="true"/>
        <material name="matplane" reflectance="0.3" texture="texplane" texrepeat="1 1" texuniform="true"/>

        <!-- <hfield name='hf1' nrow='10' ncol='10' size="5 5 .2 .1"/> -->
        <!-- <hfield name='hf1' nrow='10' ncol='10' size="5 5 .1 .1"/>  -->
        <!-- <hfield name='hf1' file='/Users/christopherxu/Downloads/mujoco-2.3.1 2/sample/data/terrainhill.png' size="2.5 2.5 .3 .99"/>  -->
        <hfield name='hf1' nrow='2' ncol='6' size="2.5 2.5 .3 .99"/> 
        <!--refer to https://github.com/osudrl/cassie-mujoco-sim/blob/master/model/cassie_hfield.xml-->
        <!--for some reason need to use full path for image file-->

    </asset>

    <worldbody>
        <geom class = "collision-default" name="floor0" pos="0.0 0.0 0.0" size="10 10 1" type="plane" condim="3" material="floorplane"></geom>

        <!-- <body name='floor' pos='0 0 0'>
            <geom name='hfield1' pos='2 0 0.00' hfield='hf1'  type='hfield'      condim='3' conaffinity='15'/>
        </body> -->



		<light directional="true" ambient="0.2 0.2 0.2" diffuse="0.8 0.8 0.8" specular="0.3 0.3 0.3" castshadow="false" pos="0 0 4" dir="0 0 -1" name="light0"></light>

		<!-- camera: front view -->
        <!-- <camera name="camera1" mode="targetbody" target="torso"/> -->

        <body name="torso" pos="0 0 0.5" euler="0 0 0"> 
        <!--0.348-->
            <joint armature="0" damping="0" limited="false" name="robot" pos="0 0 0.0" stiffness="0" type="free"/>
            <!-- <joint type = "free" limited = "false"/> -->

            <inertial pos="0.013 0 0.420"  mass="4.999" diaginertia="0.0473 0.0492 0.0231" />

			
            <geom class = 'collision-group-b' friction="0.9" type="mesh" rgba="0.79216 0.81961 0.93333 1" mesh="Torso" mass="4.999" />
 
            <site name='imu' size='0.01' pos='0.0 0.0 0.5'/> <!-- IMU height is a guess-->

            <!-- <site name="camera_vr" pos="-0.30 0 1.2"/> -->
            <!-- <site name="camera_vr" pos="0.0 0 1.2"/> -->

            <body name="Thigh_R" pos="0 0 0">
                <inertial pos="-0.0443 -0.0720 0.271" mass="0.276" diaginertia="0.000890 0.00139 0.000742" />
                <joint name="Hip_R" pos="0 0 0.321828" axis="0 1 0" frictionloss="1" limited="true" range="-0.1 0.1"/>
                <geom name="Thigh_geom_R" type="mesh" rgba="0.792157 0.819608 0.933333 1" mesh="Thigh_R" />
                <body name="Shin_R" pos="0 0 0">
                    <inertial pos="-0.0136 -0.0738 0.114" mass="0.727" diaginertia="0.00150 0.00245 0.00113" />
                    <joint name="Knee_R" pos="-0.098314 0 0.208539" axis="0 1 0"  frictionloss="1" limited="true" range="-0.1 0.1"/>
                    <geom name="Shin_geom_R" class = 'collision-group-a' type="mesh" rgba="0.792157 0.819608 0.933333 1" mesh="Shin_R" />
                    <body name="Wheel_R" pos="0 0 0">
                        <inertial pos="0 -0.1149 0.09525" mass="0.324" diaginertia="0.000851 0.00162 0.000851" />
                        <joint name="Ankle_R" pos="0 0 0.09525" axis="0 -1 0" frictionloss="0" damping="0."/>
                        <geom name="Wheel_geom_R" class = 'collision-group-a' friction = "0 0.0 0.0" type="mesh" rgba="0.898039 0.917647 0.929412 1" mesh="Wheel_R" />
                    </body>
                </body>
            </body>

            <body name="Thigh_L" pos="0 0 0">
                <inertial pos="-0.0443 0.0720 0.271" mass="0.276" diaginertia="0.000890 0.00139 0.000742" />
                <joint name="Hip_L" pos="0 0 0.321828" axis="0 1 0"  frictionloss="1" limited="true" range="-0.1 0.1"/>
                <geom name="Thigh_geom_L" class = 'collision-group-b' type="mesh" rgba="0.792157 0.819608 0.933333 1" mesh="Thigh_L" />
                <body name="Shin_L" pos="0 0 0">
                    <inertial pos="-0.0136 0.0738 0.114" mass="0.727" diaginertia="0.00150 0.00245 0.00113" />
                    <joint name="Knee_L" pos="-0.098314 0 0.208539" axis="0 1 0" frictionloss="1"  limited="true" range="-0.1 0.1"/>
                    <geom name="Shin_geom_L "class = 'collision-group-b' type="mesh" rgba="0.792157 0.819608 0.933333 1" mesh="Shin_L" />
                    <body name="Wheel_L" pos="0 0 0">
                        <inertial pos="0 0.1149 0.09525" mass="0.324" diaginertia="0.000851 0.00162 0.000851" />
                        <joint name="Ankle_L" pos="0 0 0.09525" axis="0 -1 0" frictionloss="0" damping="0."/>
                        <geom name="Wheel_geom_L" class = 'collision-group-b' friction = "0 0.0 0.0" type="mesh" rgba="0.898039 0.917647 0.929412 1" mesh="Wheel_L" />
                    </body>
                </body>
            </body>

            <body name="Shoulder_U_R" pos="0 -0.1 0">
                <inertial pos="-0.0122 -0.112 0.501" mass="0.656" diaginertia="0.0000996 0.0000653 0.0000790" />
                <joint name="Shoulder_yaw_R" pos="0.047323 0 0.501548" axis="0 1 0" />
                <geom name="Shoulder_U_geom_R" class = 'collision-group-a' type="mesh" rgba="0.792157 0.819608 0.933333 1" mesh="Shoulder_U_R"/>
                <body name="Shoulder_R" pos="0 0 0">
                    <inertial pos="0.0467 -0.120 0.518" mass="0.405" diaginertia="0.0000203 0.0000273 0.0000366" />
                    <joint name="Shoulder_roll_R" pos="0 -0.120447 0.501548" axis="1 0 0" />
                    <geom name="Shoulder_geom_R" class = 'collision-group-a' type="mesh" rgba="0.792157 0.819608 0.933333 1" mesh="Shoulder_R" />
                    <body name="Arm_R" pos="0 0 0">
                        <inertial pos="0.0510 -0.120 0.457" mass="0.681" diaginertia="0.0000915 0.0000921 0.0000490" />
                        <joint name="Shoulder_pitch_R" pos="0.051463 -0.120447 0" axis="0 0 1" />
                        <geom name="Arm_geom_R" class = 'collision-group-a' type="mesh" rgba="0.792157 0.819608 0.933333 1" mesh="Arm_R" />
                        <body name="Shank_R" pos="0 0 0">
                            <inertial pos="0.0427 -0.121 0.0337" mass="0.214" diaginertia="0.0000769 0.0000872 0.0000191" />
                            <joint name="Elbow_R" pos="0.051463 0 0.382103" axis="0 -1 0" />
                            <geom name="Shank_geom_R" class = 'collision-group-a' type="mesh" rgba="0.792157 0.819608 0.933333 1" mesh="Shank_R" />
                            <body name="Hand_R" pos="0 0 0">
                                <!-- <geom name="Hand_geo_R" class='collision-group-b' type="mesh" rgba="1 1 1 0.6"  mesh="Hand_R"/>
                                <site name="sensor_hand_R" pos="0.104 -0.120 0.189" size=".016 .016 .016" type="sphere"/> -->
                            </body>
                        </body>
                    </body>
                </body>
            </body> 

            <body name="Shoulder_U_L" pos="0 0.1 0">
                <inertial pos="-0.0122 0.112 0.501" mass="0.656" diaginertia="0.0000996 0.0000653 0.0000790" />
                <joint name="Shoulder_yaw_L" pos="0.047323 0 0.501548" axis="0 1 0" />
                <geom name="Shoulder_U_geom_L" class = 'collision-group-b' type="mesh" rgba="0.792157 0.819608 0.933333 1" mesh="Shoulder_U_L" />
                <body name="Shoulder_L" pos="0 0 0">
                    <inertial pos="0.0467 0.120 0.518" mass="0.405" diaginertia="0.0000203 0.0000273 0.0000366" />
                    <joint name="Shoulder_roll_L" pos="0 0.120447 0.501548" axis="1 0 0" />
                    <geom name="Shoulder_geom_L" class = 'collision-group-b' type="mesh" rgba="0.792157 0.819608 0.933333 1" mesh="Shoulder_L" />
                    <body name="Arm_L" pos="0 0 0">
                        <inertial pos="0.0510 0.120 0.457" mass="0.681" diaginertia="0.0000915 0.0000921 0.0000490" />
                        <joint name="Shoulder_pitch_L" pos="0.051463 0.120447 0" axis="0 0 1" />
                        <geom name="Arm_geom_L" class = 'collision-group-b' type="mesh" rgba="0.792157 0.819608 0.933333 1" mesh="Arm_L" />
                        <body name="Shank_L" pos="0 0 0">
                            <inertial pos="0.0427 0.121 0.0337" mass="0.214" diaginertia="0.0000769 0.0000872 0.0000191" />
                            <joint name="Elbow_L" pos="0.051463 0 0.382103" axis="0 -1 0" />
                            <geom name="Shank_geom_L" class = 'collision-group-b' type="mesh" rgba="0.792157 0.819608 0.933333 1" mesh="Shank_L" />
                            <body name="Hand_L" pos="0 0 0">
                                <!-- <geom name="Hand_geo_L" class = 'collision-group-b' type="mesh" rgba="1 1 1 0.6" mesh="Hand_L"/>
                                <site name="sensor_hand_L" pos="-0 0 0.4" size=".016 .016 .016" type="sphere"/> -->
                            </body>
                        </body>
                    </body>
                </body>
            </body>
            
            
        </body>

		<!-- <body name='worker' pos='0.6 0 0.5'>
            <inertial pos="0 0 0" mass="15" diaginertia="15 15 15"/>
			<geom type='box' size='.25 .25 .25' rgba='.3 .8 .7 1' class = 'collision-default'/>
            <joint type="free" stiffness="0" damping="0" frictionloss="0" armature="0"/>

			<joint name='workerx' type='slide' axis='1 0 0' limited='true' range='-100000000 100000000 ' frictionloss="15"/>
		</body>   -->


        <!-- <body name='worker' pos='1.5 0 1.5'>
            <inertial pos="0.0001 0.0001 0.0001" mass="15" diaginertia="15 15 15"/>
			<geom type='box' size='.1 .05 .05' rgba='.3 .8 .7 1' class = 'collision-default'/>
			<joint name='workerx' type='slide' axis='1 0 0' limited='true' range='-100000000 100000000 ' frictionloss="15"/>
		</body>   -->
    
    </worldbody>

    <actuator> 
        <!-- Lowed Body Actuators -->
        <motor ctrllimited="true" ctrlrange="-6 6" gear="1" joint="Hip_L"/>
        <motor ctrllimited="true" ctrlrange="-6 6" gear="1" joint="Knee_L"/>
        <motor ctrllimited="true" ctrlrange="-3 3" gear="1" joint="Ankle_L"/>

        <motor ctrllimited="true" ctrlrange="-6 6" gear="1" joint="Hip_R"/>
        <motor ctrllimited="true" ctrlrange="-6 6" gear="1" joint="Knee_R"/>
        <motor ctrllimited="true" ctrlrange="-3 3" gear="1" joint="Ankle_R"/>

        <!-- Upper Body Actuators -->
        <position ctrllimited="true" ctrlrange="-0.66 0.66" gear="1" kp="20" joint="Shoulder_yaw_L"/>
        <velocity ctrllimited="true" ctrlrange="-10 10" gear="1" kv="2" joint="Shoulder_yaw_L"/>
        <position ctrllimited="true" ctrlrange="-0.159 1.57" gear="1" kp="20" joint="Shoulder_roll_L"/>
        <velocity ctrllimited="true" ctrlrange="-10 10" gear="1" kv="2" joint="Shoulder_roll_L"/>
        <position ctrllimited="true" ctrlrange="-2.23 1.07" gear="1" kp="20" joint="Shoulder_pitch_L"/>
        <velocity ctrllimited="true" ctrlrange="-10 10" gear="1" kv="2" joint="Shoulder_pitch_L"/>
        <position ctrllimited="true" ctrlrange="-5.16 0.2" gear="2" kp="2" joint="Elbow_L"/>
        <velocity ctrllimited="true" ctrlrange="-1 1" gear="2" kv=".05" joint="Elbow_L"/>

        <position ctrllimited="true" ctrlrange="-0.66 0.66" gear="1" kp="20" joint="Shoulder_yaw_R"/>
        <velocity ctrllimited="true" ctrlrange="-10 10" gear="1" kv="2" joint="Shoulder_yaw_R"/>
        <position ctrllimited="true" ctrlrange="-1.57 0.159" gear="1" kp="20" joint="Shoulder_roll_R"/>
        <velocity ctrllimited="true" ctrlrange="-10 10" gear="1" kv="2" joint="Shoulder_roll_R"/>
        <position ctrllimited="true" ctrlrange="-1.07 2.23" gear="1" kp="20" joint="Shoulder_pitch_R"/>
        <velocity ctrllimited="true" ctrlrange="-10 10" gear="1" kv="2" joint="Shoulder_pitch_R"/>
        <position ctrllimited="true" ctrlrange="-0.2 5.16" gear="2" kp="2" joint="Elbow_R"/>
        <velocity ctrllimited="true" ctrlrange="-1 1" gear="2" kv=".05" joint="Elbow_R"/>
    </actuator>

    <sensor>
        <gyro name='torso-angular-velocity' site='imu' noise='5e-4' cutoff='44.9'/>
        <!-- <touch name="touchsensor_L" site="sensor_hand_L" />
        <touch name="touchsensor_R" site="sensor_hand_R" /> -->
    </sensor>
</mujoco>
