<mujoco model="SATYRR_NEW_V4">
    <compiler eulerseq = "zyx" angle="radian" meshdir="satyrr_wholebody/"/>
    <size njmax="-1" nconmax="-1" />
    <option integrator="RK4" timestep="0.001" solver="PGS"/>

	<default>
		<geom contype = '0' conaffinity = '0'/>
		<default class = 'collision-default'>
			<geom contype = '6' conaffinity = '0'/>
		</default>
        <default class = 'collision-group-a'>
            <geom contype = '2' conaffinity = '4'/>
        </default>
        <default class = 'collision-group-b'>
            <geom contype = '4' conaffinity = '2'/>
        </default>
    </default>

    <asset>
        <mesh name="Torso" file="Torso.STL" />
        <mesh name="Thigh_R" file="Thigh_R.STL" />
        <mesh name="Shin_R" file="Shin_R.STL" />
        <mesh name="Wheel_R" file="Wheel_R.STL" />
        <mesh name="Thigh_L" file="Thigh_L.STL" />
        <mesh name="Shin_L" file="Shin_L.STL" />
        <mesh name="Wheel_L" file="Wheel_L.STL" />
        <mesh name="Shoulder_U_L" file="Shoulder_U_L.STL" />
        <mesh name="Shoulder_L" file="Shoulder_L.STL" />
        <mesh name="Arm_L" file="Arm_L.STL" />
        <mesh name="Shank_L" file="Shank_L.STL" />
        <mesh name="Shoulder_U_R" file="Shoulder_U_R.STL" />
        <mesh name="Shoulder_R" file="Shoulder_R.STL" />
        <mesh name="Arm_R" file="Arm_R.STL" />
        <mesh name="Shank_R" file="Shank_R.STL" />
        <texture builtin="checker" height="512" name="texplane" rgb1=".2 .3 .4" rgb2=".1 0.15 0.2" type="2d" width="512"/>
        <material name="floorplane" reflectance="0.5" texrepeat="1 1" texture="texplane" texuniform="true"/>
        <material name="matplane" reflectance="0.3" texture="texplane" texrepeat="1 1" texuniform="true"/>
    </asset>

    <worldbody>
        <geom class = "collision-default" name="floor0" pos="0. 0. 0" size="0 0 1" type="plane" condim="3" material="floorplane"></geom>
		<light directional="true" ambient="0.2 0.2 0.2" diffuse="0.8 0.8 0.8" specular="0.3 0.3 0.3" castshadow="false" pos="0 0 4" dir="0 0 -1" name="light0"></light>

		<!-- camera: front view -->
        <camera name="camera1" mode="targetbody" target="torso"/>

        <body name="torso" pos="0 0.0 0.4869">
            <!--<joint armature="0" damping="0" limited="false" name="robot" pos="0 0 0.0" stiffness="0" type="free"/> -->
            <joint axis = "1 0 0" pos = "0 0 0" name = "move_x" type = "slide" limited = "false"/>
			<joint axis = "0 1 0" pos = "0 0 0" name = "move_y" type = "slide" limited = "false"/>
			<joint axis = "0 0 1" pos = "0 0 0" name = "move_z" type = "slide" limited = "false"/>
			<joint axis = "1 0 0" pos = "0 0 0" name = "rotate_roll" type = "hinge" limited = "false"/>
			<joint axis = "0 1 0" pos = "0 0 0" name = "rotate_pitch" type = "hinge" limited = "false"/>
			<joint axis = "0 0 1" pos = "0 0 0" name = "rotate_yaw" type = "hinge" limited = "false"/>
            <geom class = 'collision-group-a' friction="0.9" type="mesh" rgba="0.79216 0.81961 0.93333 1" mesh="Torso" mass="4.05" />
 
            <site name="camera_vr" pos="-0.30 0 1.2"/>

            <!-- <site name="camera_vr" pos="0.0 0 1.2"/> -->

            <body name="Thigh_R" pos="-0.06625 0 0.36">
                <inertial pos="0 -0.080175 -0.0380315" quat="0.707107 0 0 0.707107" mass="0.904864" diaginertia="0.00325713 0.00280128 0.000871858" />
                <joint name="Hip_R" pos="0 0 0" axis="0 -1 0" />
                <geom name="Thigh_geom_R" class = 'collision-group-a' type="mesh" rgba="0.792157 0.819608 0.933333 1" mesh="Thigh_R" />
                <body name="Shin_R" pos="0 -0.080175 -0.15">
                    <inertial pos="0 0 -0.0789246" quat="0.707107 0 0 0.707107" mass="0.394882" diaginertia="0.00112813 0.00112607 0.000173116" />
                    <joint name="Knee_R" pos="0 0 0" axis="0 -1 0" />
                    <geom name="Shin_geom_R" class = 'collision-group-a' type="mesh" rgba="0.792157 0.819608 0.933333 1" mesh="Shin_R" />
                    <body name="Wheel_R" pos="0 0 -0.15" quat="0.707107 0 0 -0.707107">
                        <inertial pos="0.0356257 0 0" mass="0.52599" diaginertia="0.000948894 0.000489944 0.000489944" />
                        <joint name="Ankle_R" pos="0 0 0" axis="1 0 0" />
                        <geom name="Wheel_geom_R" class = 'collision-group-a' friction = "0 0.0 0.0" type="mesh" rgba="0.898039 0.917647 0.929412 1" mesh="Wheel_R" />
                    </body>
                </body>
            </body>

            <body name="Thigh_L" pos="-0.06625 0 0.36">
                <inertial pos="0 0.080175 -0.0380315" quat="0.707107 0 0 0.707107" mass="0.904864" diaginertia="0.00325713 0.00280128 0.000871858" />
                <joint name="Hip_L" pos="0 0 0" axis="0 -1 0" />
                <geom name="Thigh_geom_L" class = 'collision-group-b' type="mesh" rgba="0.792157 0.819608 0.933333 1" mesh="Thigh_L" />
                <body name="Shin_L" pos="0 0.080175 -0.15">
                    <inertial pos="0 0 -0.0789246" quat="0.707107 0 0 0.707107" mass="0.394882" diaginertia="0.00112813 0.00112607 0.000173116" />
                    <joint name="Knee_L" pos="0 0 0" axis="0 -1 0" />
                    <geom name="Shin_geom_L "class = 'collision-group-b' type="mesh" rgba="0.792157 0.819608 0.933333 1" mesh="Shin_L" />
                    <body name="Wheel_L" pos="0 0 -0.15">
                        <inertial pos="0 0.0363743 0" quat="0.707107 0 0 0.707107" mass="0.52599" diaginertia="0.000948894 0.000489944 0.000489944" />
                        <joint name="Ankle_L" pos="0 0 0" axis="0 -1 0" />
                        <geom name="Wheel_geom_L" class = 'collision-group-b' friction = "1 0.0 0.0" type="mesh" rgba="0.898039 0.917647 0.929412 1" mesh="Wheel_L" />
                    </body>
                </body>
            </body>

            <body name="Shoulder_U_L" pos="-0.06625 0.13274 0.48068">
                <inertial pos="5.98242e-08 -3.82379e-09 0.0467603" quat="0.5 0.5 0.5 0.5" mass="0.246892" diaginertia="0.0012863 0.00103844 0.00030284" />
                <!-- <joint name="Shoulder_yaw_L" pos="0 0 0" axis="0 0 1" /> -->
                <geom name="Shoulder_U_geom_L" class = 'collision-group-b' type="mesh" rgba="0.792157 0.819608 0.933333 1" mesh="Shoulder_U_L" />
                <body name="Shoulder_L" pos="0 0 0.114214">
                    <inertial pos="-7.6505e-09 4.57848e-09 2.98572e-10" quat="0.500001 0.499999 0.499999 0.500001" mass="0.225611" diaginertia="0.000280653 0.000166998 0.000150663" />
                    <!-- <joint name="Shoulder_roll_L" pos="0 0 0" axis="1 0 0" /> -->
                    <geom name="Shoulder_geom_L" class = 'collision-group-b' type="mesh" rgba="0.792157 0.819608 0.933333 1" mesh="Shoulder_L" />
                    <body name="Arm_L" pos="0 0 0">
                        <inertial pos="0 0.0494924 -0.061196" quat="0.707074 0.00680441 -0.00680441 0.707074" mass="0.584971" diaginertia="0.00283895 0.00259254 0.000369078" />
                        <!-- <joint name="Shoulder_pitch_L" pos="0 0 0" axis="0 1 0" /> -->
                        <geom name="Arm_geom_L" class = 'collision-group-b' type="mesh" rgba="0.792157 0.819608 0.933333 1" mesh="Arm_L" />
                        <body name="Shank_L" pos="0 0.05082 -0.204">
                            <inertial pos="9.76797e-09 0 -0.0687371" quat="0.707107 0 0 0.707107" mass="0.111225" diaginertia="0.000216628 0.00021518 1.39816e-05" />
                            <!-- <joint name="Elbow_L" pos="0 0 0" axis="0 1 0" /> -->
                            <geom name="Shank_geom_L" class = 'collision-group-b' type="mesh" rgba="0.792157 0.819608 0.933333 1" mesh="Shank_L" />
                        </body>
                    </body>
                </body>
            </body>
            
            <body name="Shoulder_U_R" pos="-0.06625 -0.13274 0.48068">
                <inertial pos="5.98242e-08 -3.82379e-09 0.0467603" quat="0.5 0.5 0.5 0.5" mass="0.246892" diaginertia="0.0012863 0.00103844 0.00030284" />
                <!-- <joint name="Shoulder_yaw" pos="0 0 0" axis="0 0 1" /> -->
                <geom name="Shoulder_U_geom_R" class = 'collision-group-a' type="mesh" rgba="0.792157 0.819608 0.933333 1" mesh="Shoulder_U_R" />
                <body name="Shoulder_R" pos="0 0 0.114214">
                    <inertial pos="-7.6505e-09 4.57848e-09 2.98572e-10" quat="0.500001 0.499999 0.499999 0.500001" mass="0.225611" diaginertia="0.000280653 0.000166998 0.000150663" />
                    <!-- <joint name="Shoulder_roll" pos="0 0 0" axis="1 0 0" /> -->
                    <geom name="Shoulder_geom_R" class = 'collision-group-a' type="mesh" rgba="0.792157 0.819608 0.933333 1" mesh="Shoulder_R" />
                    <body name="Arm_R" pos="0 0 0">
                        <inertial pos="0 -0.0494924 -0.061196" quat="0.707074 -0.00680441 0.00680441 0.707074" mass="0.584971" diaginertia="0.00283895 0.00259254 0.000369078" />
                        <!-- <joint name="Shoulder_pitch_R" pos="0 0 0" axis="0 -1 0" /> -->
                        <geom name="Arm_geom_R" class = 'collision-group-a' type="mesh" rgba="0.792157 0.819608 0.933333 1" mesh="Arm_R" />
                        <body name="Shank_R" pos="0 -0.05082 -0.204">
                            <inertial pos="-9.76797e-09 0 -0.0687371" quat="0.707107 0 0 0.707107" mass="0.111225" diaginertia="0.000216628 0.00021518 1.39816e-05" />
                            <!-- <joint name="Elbow_R" pos="0 0 0" axis="0 -1 0" /> -->
                            <geom name="Shank_geom_R" class = 'collision-group-a' type="mesh" rgba="0.792157 0.819608 0.933333 1" mesh="Shank_R" />
                        </body>
                    </body>
                </body>
            </body> 
        </body>
        
    </worldbody>

    <actuator> 
        <!-- <position ctrllimited="true" ctrlrange="-10.0 10.0" gear="100" kp="0.01" joint="x"/>
        <position ctrllimited="true" ctrlrange="-2.8 2.8" gear="100" kp="0.01" joint="theta"/>
        <velocity ctrllimited="true" ctrlrange="-1.0 1.0" gear="100" kv="0.001" joint="x"/>
        <velocity ctrllimited="true" ctrlrange="-2.8 2.8" gear="100" kv="0.001" joint="theta"/> -->
        <motor ctrllimited="true" ctrlrange="-100.0 100.0" gear="1" joint="Hip_L"/>
        <motor ctrllimited="true" ctrlrange="-100.0 100.0" gear="1" joint="Knee_L"/>
        <motor ctrllimited="true" ctrlrange="-100.0 100.0" gear="1" joint="Ankle_L"/>
        <motor ctrllimited="true" ctrlrange="-100.0 100.0" gear="1" joint="Hip_R"/>
        <motor ctrllimited="true" ctrlrange="-100.0 100.0" gear="1" joint="Knee_R"/>
        <motor ctrllimited="true" ctrlrange="-100.0 100.0" gear="1" joint="Ankle_R"/>
    </actuator>
</mujoco>
